Workbook

Sheet Project Sheet 6
A1: Project Code | B1: Email Receiver | C1: email Sender | D1: Subject Line | E1: Date of email | F1: CC | G1: Email Body | H1: Customer Requirement Extract from email Body | I1: Sender DETAILS | J1: Web Links Picture hyperlinks Attachement | K1: Inside Comments | L1: LINKS STATUS | M1: ACKNOWEDGMENT | N1: Analysis of Customer Enquiry | O1: Database Prepared by Saad/Kaif/Zafar/Maaz | P1: Enquiry Analysis & links provided by | Q1: Enquiry Letter Made and Sent by | R1: Supplier email checked Yasir/Saad/ Arsalan/Zafar | S1: Price Calculated by Arsalan | T1: Quotation Prepared by | U1: Quotation Follow up done by | V1: Order Processed By | W1: Payment Follow up Done by | X1: Number of Quotation Received | Y1: Name of Database | Z1: Weblinks | AA1: Weblink status
A2: FEZW-XWQ-LQ
A3: ADAX-XQP-YA
A4: ANZF-FWR-JF
A5: VFIZ-YAI-QZ
A6: FMRB-BOR-ZB
A7: SULZ-ZFD-QZ
A8: QQOT-TKM-SO
A9: ZINY-YNI-PY
A10: HODL-LKS-DL
A11: SHHH-HWU-FH
A12: XZMI-IEB-NI
A13: YYMF-FNS-LY
... A1725: YCIW-SRO-JS

Sheet Project Sheet 5
A1: Project Code | B1: Internal Status | C1: Project External Process | D1: Enquiry Came through | E1: Date of enquiry | F1: Customer Requirement Arsalan | G1: CUSTOMER DETAILS | H1: Comments ANY ONE | I1: Enquiry Arrival Date | J1: LINKS STATUS | K1: ACKNOWEDGMENT | L1: Analysis of Customer Enquiry Zafar | M1: Database Prepared by Saad/Kaif/Zafar/Maaz | N1: Enquiry Analysis & links provided by | O1: Enquiry Letter Made and Sent by | P1: Supplier email checked Yasir/Saad/ Arsalan/Zafar | Q1: Price Calculated by Arsalan | R1: Quotation Prepared by | S1: Quotation Follow up done by | T1: Order Processed By | U1: Payment Follow up Done by | V1: Number of Quotation Received | W1: Name of Database | X1: Weblinks | Y1: Weblink status
A2: NFX-KY-AD | B2: Inquiry received by e-mail | F2: labmaster neo | G2: Ahmad Muslim. Product & Process Innovation Dept. (PPID) Qarshi Brands Pvt. Ltd. Hattar, KPK. ahmad.muslim@qarshi.com
A3: NFX-KY-AD | B3: Inquiry received by e-mail | F3: labmaster neo | G3: Ahmad Muslim. Product & Process Innovation Dept. (PPID) Qarshi Brands Pvt. Ltd. Hattar, KPK. ahmad.muslim@qarshi.com
A4: LTL-LJ-SI | B4: Quotation Sent | F4: FLUX PUMP | G4: AGP FAROOQ HAYAT Masab Ejaz
A5: AKC-FH-RL | B5: Inquiry received by e-mail | F5: Clutch Break | G5: AGP FAROOQ HAYAT
A6: PCI-SD-DO | B6: Inquiry received by e-mail | F6: Moisture Analyzer MS-70 A&D Japan MX-50 A&D Japan pH Meter HI-5222 Hanna USA | G6: Ahmad Muslim. Product & Process Innovation Dept. (PPID) Qarshi Brands Pvt. Ltd. Hattar, KPK.
A7: NAU-WJ-MT | B7: Quotation Sent | F7: VOC meter. | G7: Haider Ali |Manager EHS DIC Pakistan Limited A: Head office: Shahrah-e-Roomi,P.O. Amer Sidhu, Lahore-54760, Pakistan Karachi office: Plot # 06 Sector 28, Korangi Industrial Area, Karachi, Pakistan M: +92-301-8427331 P: +92-42-35822178-80, Ext.: 235 | H7: LAST ORDER Portable Gas Detector for VOCs (PGM-1800
A8: MHY-OF-NW | B8: Quotation Sent | F8: Sifter 1 stage stainless steel | G8: Asian Continental Address: D-32, S.I.T.E.ll,super Highway, Karachi Pakistan. Phone: (021) 36881775-8
A9: FYL-SA-GF | F9: Vibrator controller SDVC11-S EA 3 Vibrator Controller SDVC31-M EA 3 DHT11 Temperature and Humidity sensor EA 2 Sick Sensor wfs3-40p415 EA 1 | G9: Hussain Riaz | Associate Manager Procurement Address: C-14 SITE, Karachi, Pakistan Work: +(92-21) 32573391-5 | Ext: 387 Cell: +(92) 333 3829055 Email:Hussain.riaz@searlecompany.com
A10: JOR-QY-NP | B10: Request for further information sent to customer | F10: Synthetic Bag Filter 80-85% 3 Pockets 10 Pcs AAF Brand Synthetic Bag Filter 80-85% 6 Pockets 17 Pcs AAF Brand Synthetic Pre-Filters G4, 2'x2', 40-45% 10 Pcs AAF Brand Synthetic Pre-Filters G4, 1'x2', 40-45% 10 Pcs AAF Brand | G10: Tufail Khan Procurement Officer Ferozsons Laboratories Limited Post Office: Ferozsons, Amangarh, Nowshera, K.P.K. Phone: 0923-560145 | Cell: 0315-9890785
A11: GTR-QC-VO | B11: Quotation Sent | F11: DC/Potentiometer Converter (Model: CVR1) | G11: Saad Munir Engineering Store Officer, GSK Plot 5, Sector 21, Korangi Industrial Area, Karachi-74900, Pakistan Email saad.a.munir@gsk.com Mobile +92 312 370 9655 | +92 300 788 9092 Tel : 35205119-20 Ext:3084
A12: AYS-LJ-WB | B12: Quotation Sent | F12: Industrial Plug (5 Pin 32 Amp) 8571/12-506 STAHL 1 | G12: Mirza Imran Baig Senior Buyer, In-direct Sourcing Procurement, Pakistan Email mirzaimran.x.baig@haleon.com Haleon Pakistan Limited (Formerly GSK Consumer Healthcare Pakistan Ltd) 11-A, 11th Floor, Sky Tower (East Wing) Dolmen City, HC-3, Block-4, Marine Drive, Clifton Karachi-75600, Pakistan
A13: BLM-YY-PZ | F13: Thermal Insulation and Resistance Gloves Qty. 06 pairs. | G13: Mirza Imran Baig Senior Buyer, In-direct Sourcing Procurement, Pakistan Email mirzaimran.x.baig@haleon.com Haleon Pakistan Limited (Formerly GSK Consumer Healthcare Pakistan Ltd) 11-A, 11th Floor, Sky Tower (East Wing) Dolmen City, HC-3, Block-4, Marine Drive, Clifton Karachi-75600, Pakistan
A14: QLI-VW-HI | F14: Schneider Auxillary relay GVAN11 EA 12 Wecon LX2e PLC EA 1 Wecon HMI 7" LEVI2070D EA 1 Fatek PLC FBS-232P0 DB9 cable EA 2 | G14: Hussain Riaz | Associate Manager Procurement Address: C-14 SITE, Karachi, Pakistan Work: +(92-21) 32573391-5 | Ext: 387 Cell: +(92) 333 3829055 Email:Hussain.riaz@searlecompany.com
A15: HST-GT-TD | F15: color waize 26/10x43mm art no: 43600008 qty 20 Brand ETIBE | G15: BLI ASJAD
A16: KNZ-KH-SV | B16: Quotation Sent | F16: DRV5.V.2.1 Manufactured by ENDEX INC PARKER: STEPPER DRIVE (OEM750) | G16: BF BIO
A17: QNR-VP-HP | F17: Jenco 3177 3177M Conductivity/TDS/Salinity Basis Benchtop Meter | G17: Shakeel Ahmed Pharmaceutical
A18: LAR-UQ-BW | F18: HACH Spectrophotometer FLAME PHOTOMETER PH METER Dr 2800 Jenway with potassium filter | G18: Qadir chemicals Sobiaqumber48@gmail.com
A19: CZZ-GI-HI | F19: data logger -20 to 50 degree Qty 12 | G19: mavenhealthcare@gmail.com
A20: WAA-GC-YX | F20: Price labeler pagination device Blitz 2682 | G20: OTSUKA Talib hussain
A21: SWE-QM-CB | F21: TH4M Series LCD Temperature/Humidity Controllers | G21: OTSUKA Talib hussain
A22: UZP-QV-TX | B22: Quotation Sent | F22: THREE-PHASE VACUUM CLEANER FOR DUST, SOLIDS AND LIQUIDS DG 70 EXP, 5,5 KW | G22: Muhammad Zeeshan Mobile No.: 0335-2565477 Tel. Nos. ++92-21-35121963 - 64 Ext No. 2216 Healthtek (Pvt.)Limited
A23: AVW-LB-JJ | B23: Request for further information sent to customer | F23: 01: LoadSure Element QTY: 01 (As per Picture No: 2) 02: Tubing for material Transfer with Triclover end QTY: 04 Bore 10mm, Outer Dia 18mm, length 05Meters Triclover Outer Dia 25mm (As per picture No: 1) (As per picture No: 3) With food grade Certification Transferring Materials, Alcohol & Dimethylamine | G23: Contact Person is Mr. Faisal Aman Thanks and regards, Mirza Imran Baig Senior Buyer, In-direct Sourcing Procurement, Pakistan Email mirzaimran.x.baig@haleon.com
A24: TTF-JR-OS | B24: Quotation Sent | F24: Movable and Adjustable Conveyor as per below picture | G24: Mirza Imran Baig Senior Buyer, In-direct Sourcing Procurement, Pakistan Email mirzaimran.x.baig@haleon.com
A25: CAP-ON-SQ | B25: Quotation Sent | F25: Magnetic Stirerr for tank (1.1 to 1.5 KV) SS 316-L Qty-01 | G25: Tufh Engineering Javed Bhai
A26: QVY-XU-ZT | F26: 316L magnetic stirrer 1.5 kw class IE3 & 1.1 Kw class IE3 2 Nos 3 phase
A27: VWX-CZ-TU | F27: 60 100 150L stirrer tank | G27: Shahid Iqbal Sami pharma
A28: KVJ-AJ-QP | B28: Quotation Sent | F28: Hand crimping tool for 32mm vial cap | G28: Asad BF BIO
A29: CWG-RX-OS | B29: Quotation Sent | F29: Silicone Flexible Heating Foil Element Size: 0.8 x 365 x 165 mm with 8 holes, dia. 15 mm Voltage: 230 V | Power: 1500 W Connection: 2 x RHH 200mm cable Manufacturer: Uhlmann Origin: Sweden | G29: muhammad.jawad@agp.com.pk
A30: RFK-DP-UD | B30: Quotation Sent | F30: Conned Motor Pump for Refrigeration Model NR 100-50B/212 H4 – E-% Power 2.2 Kw Flow 20.75 M3/H Head 7.5m Speed 2900ROM Freq 50 Hz Volt. 400 V AMP 5.8A Pressure 0.5 Mpa NPS Hr 0.45m Star AMP 24 A Insulation Grade H Temp 90 oC Protection grade IP 54 Weight 4Pkg Order No X 7188 62-990 2 Serial No 6zn1403010 Do Not turn power on weight liquid Hefei X | G30: Mirza Imran Baig Senior Buyer, In-direct Sourcing Procurement, Pakistan Email mirzaimran.x.baig@haleon.com
A31: KKG-HU-YN | B31: Inquiry received by e-mail | F31: SS 316L mesh 3feet x 3feet mesh size=3MM 1 no SS 316L mesh 3feet x 3feet mesh size=1.5MM 1 no | G31: Ashraf Butt Procurement Officer Ashraf.x.butt@haleon.com Haleon Pakistan Limited (Formerly GSK Consumer Healthcare Pakistan Ltd) 11-A, 11TH floor, Sky Tower (East Wing) Dolman City, HC-3, Block 4, Marine Drive, Clifton, Karachi. Call : 03003567144
A32: SNL-IJ-QW | F32: SUBMERSIBLE WASTEWATER PUMPS SEG.50.40.2.50B +4kW /2 pole | G32: Agha khan hospital
A33: NTK-EE-YX | F33: Description Qty. Unit Clean Steam Supply system " 316L Stainless Steel as per ASME BPE 1.65mm thick internally polished (less than 0.5 microns) tubing for Purified water distribution loops. The piping to be of ALFA LAVAL." 25 mm Dia NB' 20 RFT "SS 316L elbow 90 degree 0.5 micron internal finish wall thickness 1.65 mm 25 mm dia" 10 Nos The valves and specialties shall be Spirax or approved equal. Steam traps, steam PRVs and other steam specialties to be only of SPIRAX SARCO. "Steam isloation /shutoff ball valve M70I AND M80I SANITARY BALL VALVES with ferrule type 20 mm dia" 4 NO "SS 316L Check valves. Dia 20 mm" "SS 316L Thermodynamic Steam Traps for clean steam application, ferrule connections with ferrule triclover clamps pressure PN 10 Temperature max 150 C Dia 20 mm" 4 No | G33: Ahmed Ali Baig | Deputy Manager Supply Chain M/s. Healthtek (Pvt.) Limited | Plot No. 14 Sector 19, Korangi Industrial Area, Karachi-74900 Phone: +92 21 35121963-64 | Ext: 2215 | Cell: +92 321 2128947, +92 303 0724067
A34: EAO-OB-OY | B34: Quotation Sent | F34: TESTOMAT WATER HARDNESS TESTER Model: TH 2005 | G34: ASJAD
A35: BUW-VV-QW | F35: Sloan SD-150 - JUMPSUIT, NON SKID, DISPOSABLE, 50 EA/CS
A36: ADV-WS-IC | F36: GE 4c convex probe | G36: RM Technical Services Islamabad
A37: RPF-EP-AV | B37: Inquiry received by e-mail | F37: SERVO MOTOR, SM100/40/050/P0/45/M1/B1, M 4 EA SERVO MOTOR, SM100/50/030/P0/45/M1/B1, M 2 EA SERVO-MOTOR, SM100/50/030/P0/45/S1/B0, M 4 EA SERVO MOTOR, SH100/40060/0/0/00/00/00/00 2 EA SERVO MOTOR, SH055/80013/0/0/00/00/00/00 2 EA MULTI DRIVE CONTROLLER C400/F.8 AXLES, M 2 EA MULTI-AXLE CONTROLLER MAX 4 F.8 AXLES, M 1 EA MOTOR CONTROLLER MC-4 (10A), MAKE SCHNEI 5 EA | G37: Hussain Riaz Associate Manager Procurement I Supply Chain Getz Pharma
A38: WBZ-KG-EY | F38: 00010 PLC make: Mitsubishi Model: FX3U 32MR Power: 220v AC 00020 HMI screen, Make: Mitsubishi Model: E1061 Note: All above parts required for Autoclav | G38: M. Faraz Khatri Senior Associate Manager Engineering Procurement| Ext:516 Martin Dow Limited Based at Korangi Plant, Karachi. Plot No. 37, Sector 19, Korangi Industrial Area, Karachi-74900, Pakistan
A39: TFM-CQ-TK | B39: Quotation Sent | F39: 00010 Digital Temperature Controller TZ4L-14R Sensor: Multi range, Range= Multi Range Out= Relay Power: 100 to 240v AC Made in Korea Required for Accela Coata 1 and 2, Glatt Fluid Bed Dryer and Liquid steam tank. 8 ea. 00020 Temperature controller make: Shinko Model no. JCM-33A-A/M (G) VCC= 100 - 240v ac input source= PT100, 0 TO 200°c Size= 72 x 72mm Made in Japan. Required for Fluid Bed Dryer make: YENCHEN 3 Ea. 00030 Proximity Switch 1A0032/Ae2010 EA 12.000 00040 Magnetic Contactor SW80-1 2 Ea. | G39: =G38 -> M. Faraz Khatri Senior Associate Manager Engineering Procurement| Ext:516 Martin Dow Limited Based at Korangi Plant, Karachi. Plot No. 37, Sector 19, Korangi Industrial Area, Karachi-74900, Pakistan
A40: QRB-PR-EA | B40: Inquiry received by e-mail | F40: DC Drive, make: ABB (VERITRON) Type: GCB 1302 A Supply: AC 220v (48-63hz) Output: DC 185v (4.5A 2 Ea. | G40: =G39 -> M. Faraz Khatri Senior Associate Manager Engineering Procurement| Ext:516 Martin Dow Limited Based at Korangi Plant, Karachi. Plot No. 37, Sector 19, Korangi Industrial Area, Karachi-74900, Pakistan
...

Sheet Project Sheet 4
A1: Project Code | B1: Internal Status | C1: Project External Process | D1: Enquiry Came through | E1: Date of enquiry | F1: Customer Requirement Arsalan | G1: CUSTOMER DETAILS | H1: Comments ANY ONE | I1: Enquiry Arrival Date | J1: LINKS STATUS | K1: ACKNOWEDGMENT | L1: Analysis of Customer Enquiry Zafar | M1: Database Prepared by Saad/Kaif/Zafar/Maaz | N1: Enquiry Analysis & links provided by | O1: Enquiry Letter Made and Sent by | P1: Supplier email checked Yasir/Saad/ Arsalan/Zafar | Q1: Price Calculated by Arsalan | R1: Quotation Prepared by | S1: Quotation Follow up done by | T1: Order Processed By | U1: Payment Follow up Done by | V1: Number of Quotation Received | W1: Name of Database | X1: Weblinks | Y1: Weblink status
A2: ABFQ-EKZ-CF | B2: Closed | F2: 1. Worm Gear Box 1:50 Ratio Size 70 nos 2. Motor 1440rpm 2Hp single phase 3. Motor 1440rpm 3Hp three phase | G2: Mohsin Javed FABRICON(PRIVATE) LTD 46-247, Sector: 24, Korangi Industrial Area, Karachi – 74900, Pakistan Pakistan 92-331-5064957 / 92-21-35067736 mohsinjaved@fabricon.com.pk
A3: ABII-JOQ-UJ | B3: Quotation Sent | F3: 20 HP of 2P/2900RPM 3-Ph/400V TEFC Electric Motor (1 Unit) | G3: mueez.ansari@kineticflowsystems.com Syed Zahid Hasan
A4: ADCJ-USH-ZJ | B4: Inquiry received by e-mail | F4: Dissolution Test Apparatus, Model-PTWS 1220 12 position Tablet Instrument with Full IQ and OQ with External Pinter Facility Pharma Test Tablet Dissolution, Tester PT –DT70 instrument with Printers Model PT-RP80 Pharma Test Germany or any best Quality Brand | G4: Afzal Ghani, PROCUREMENT OFFICER Postal Address: P.O Ferozsons, Amangarh, Nowshera, K.P.K, |pro.nowshera@ferozsons-labs.com|Website:www.ferozsons-labs.com|0923-650145, 0312-9486757,03458553396|FAX: 0923-611302|
A5: ADFX-PJC-OA | B5: Inquiry received by e-mail | F5: Polarimeter Digital Model ADP 450 Bellingham & Stanley Instrument with Pinter Model CBM 910 Bellingham & Stanley , Made in England or any best Quality Brand | G5: Afzal Ghani, PROCUREMENT OFFICER Postal Address: P.O Ferozsons, Amangarh, Nowshera, K.P.K, |pro.nowshera@ferozsons-labs.com|Website:www.ferozsons-labs.com|0923-650145, 0312-9486757,03458553396|FAX: 0923-611302|
A6: ADLY-CEM-VP | B6: Quotation Sent | F6: Digital Multimeter 87V Max Fluke 1 Digital Multimeter CD800b Sanwa 2 | G6: Ashraf Butt CHC Procurement Officer GlaxoSmithKline CHC Pakistan Limited. 35 - Dockyard Road, west wharf , Karachi-74000, Pakistan Tel: +92 21 32315478-82 & (Dir) 35274744 UAN:+92 21 111 475 725 (Ext: 4744)
A7: ADOI-SAV-BU | B7: Quotation Sent | F7: BECKER vacuum pump motor type D 71 B4 P motor no : 15085540 nample attached | G7: Ashraf Butt CHC Procurement Officer GlaxoSmithKline CHC Pakistan Limited. 35 - Dockyard Road, west wharf , Karachi-74000, Pakistan Tel: +92 21 32315478-82 & (Dir) 35274744 UAN:+92 21 111 475 725 (Ext: 4744) | K7: Send
A8: AEIH-LDM-MW | B8: Quotation Sent | F8: GAS REGULATOR Model AG/RC DN25 MAKE MADAS Italy | G8: Gunj Glass Head Office: A-26 Site Area Karachi Info@gunjglass.com Tell: 0213-2414862 | K8: Send
A9: AEIL-PXX-JJ | B9: Inquiry received by e-mail | F9: Heat Exchanger plate with epdm gasket model NT150 LH, plate thickness 0.5mm, material 316L qty 136 pcs model VT 80 LH, plate thisckness 0.5mm 316L qty 26 | G9: HASSAN ENGINEERING R-712 sector-15A/5 Buffer zone,North karachi, phone 021-36999059 cell: 0305-2108958 saleem.he_engg@yahoo.com | K9: Send
A10: AEVM-AQR-PS | B10: Closed | F10: Automatic Hand Dryer-220 V-AC,1800 Watt ,White Siemens 2 | G10: Asim Laique Assistant Manager Procurement Cell #0345-3127098 asim.laiq@herbion.com | H10: 8,500 price local available
A11: AEZO-PYA-KX | F11: Metal Detector 4 • Type of tablets both round and oblong. • Speed up to 300,000 to 400,000 tablets per hour | G11: Pharmevo
A12: AFCH-CKO-SE | F12: BALL, CHECK ( PTFE ) P/N 050.018.600, DIAPHRAGM PUMP SIZE: 2" 21/05/26BAL. 4.000 BALL, CHECK ( PTFE ) RS MODEL: S20B1AGTANS000 TYPE: A.0.D.D. PUMP MAKE: SAND PIPER PUMP Approved 29868/002 280424899 .00000 PC 2.000 .00 LE 21/07/15 00000 .00 E13 BUYER J RUBBER DIAPHRAGM 2" P/N 286.007.365, DIAPHRAGM PUMP SIZE: 2" 21/05/26BAL. 2.000 RUBBER DIAPHRAGM 2" RS MODEL: S20B1AGTANS000 TYPE: A.0.D.D. PUMP MAKE: SAND PIPER PUMP Approved 29868/003 280424900 .00000 PC 2.000 .00 LE 21/07/15 00000 .00 E13 BUYER J DIAPHRAGM ( PTFE OVERLAY ) P/N 286.020.604, DIAPHRAGM PUMP SIZE: 2" 21/05/26BAL. 2.000 DIAPHRAGM ( PTFE OVERLAY ) RS MODEL: S20B1AGTANS000 TYPE: A.0.D.D. PUMP MAKE: SAND PIPER PUMP Approved 29868/004 280424901 .00000 PC 4.000 .00 LE 21/07/15 00000 .00 E13 BUYER J SEAT, VALVE ( TEFLONE ) P/N 722.040.600, DIAPHRAGM PUMP SIZE: 2" 21/05/26BAL. 4.000 SEAT, VALVE ( TEFLONE ) RS MODEL: S20B1AGTANS000 TYPE: A.0.D.D. PUMP MAKE: SAND PIPER PUMP Approved 29868/005 280424902 .00000 PC 1.000 .00 LE 21/07/15 00000 .00 E13 BUYER J ROD, DIAPHRAGM P/N 685.058.120, DIAPHRAGM PUMP SIZE: 2" 21/05/26BAL. 1.000 ROD, DIAPHRAGM RS MODEL: S20B1AGTANS000 TYPE: A.0.D.D. PUMP MAKE: SAND PIPER PUM
A13: AGDT-OVW-WT | B13: Inquiry received by e-mail | F13: Specification of fillter Fillter coller size 15 x15 inches Fillter pockets size 18x13 inches Fillter pocket 09 With fillter pockets gripping spring As per sample | G13: Ashraf Butt CHC Procurement Officer GlaxoSmithKline CHC Pakistan Limited. 35 - Dockyard Road, west wharf , Karachi-74000, Pakistan Tel: +92 21 32315478-82 & (Dir) 35274744 UAN:+92 21 111 475 725 (Ext: 4744) | K13: Send
A14: AGYM-EMX-TO | B14: Inquiry received by e-mail | F14: PSR 11 – 21 Oxygen sensor qty 1 OX – 3 Oxygen sensor qty 1 | G14: Archroma Pakistan Limited | Plot #LX-10 & LX11 Landhi Industrial Trade Zone Karachi 74900 | Pakistan Tel: +9221 35081371-72 | Mobile: +92306 2349660 | E-Mail: bashir.ahmed@archroma.com | K14: Send
A15: AHBM-QME-HX | B15: Quotation Sent | F15: BRAKE RECTIFIER BG 1.5 FOR SEW MOTORS - AT PACKING PLANT PART NO 8- 253 846 FOR FA40/G DT100LS4/BMG EA 04 | G15: ='Projects sheet 3'!G980 -> Riffat Tahira Procurement Officer Processing Section Department of Procurement Bestway Cement Limited | 8th Floor | UBL Building, Jinnah Avenue | Islamabad 44000, Pakistan. Tel: +92 51 835 5139 | UAN:+92 51 111 111 722 EXT: 324 Website: www.bestway.com.pk E-mail: riffat.tahira@bestway.com.pk | H15: Riffat Tahira | K15: Send
A16: AHHN-KCV-BA | B16: Quotation Sent | F16: REXROTH DOOR LOCK MNR: 3 842 530 352 qty 50 | G16: Business Links Int’l (Pvt) Ltd Address: 2nd Floor, Twin Star Chambers, Mumtaz Hasan Road, Karachi, Pakistan Phone: + 92 21 3241 9227 asjad@businesslinks-pk.com | H16: G9T-PQ5-JWI-X5U4
A17: AHRY-LFE-QJ | F17: GEARED MOTOR, TYPE=RF27DRE80M4 ITEM # 646BW410-M01, 0.75 KW, 4- -POLE, 400 VAC, MAKE = SEW EURO DRIVE EA 06 | G17: ='Projects sheet 3'!G912 -> Muhammad Rehan Anwar Officer Procurement Department of Procurement Bestway Cement Limited | 8th Floor | UBL Building, Jinnah Avenue | Islamabad 44000, Pakistan. Tel: +92 51 835 5118 | Fax: +92 51 265 4865 | UAN:+92 51 111 111 722 Website: www.bestway.com.pk CC: rehan.anwar@bestway.com.pk mahboob.shakir@bestway.com.pk | K17: Send
A18: AIOO-RXH-AQ | F18: GEAR UNIT, 11KW, 1400 RPM, I=137 CRLB147-137-M11+E30- B5-0-ZS06615 FOR ROTARY FEEDER, BONENG FOR LINE-II EA 01 | G18: =G17 -> Muhammad Rehan Anwar Officer Procurement Department of Procurement Bestway Cement Limited | 8th Floor | UBL Building, Jinnah Avenue | Islamabad 44000, Pakistan. Tel: +92 51 835 5118 | Fax: +92 51 265 4865 | UAN:+92 51 111 111 722 Website: www.bestway.com.pk CC: rehan.anwar@bestway.com.pk mahboob.shakir@bestway.com.pk | K18: Send
A19: AJFA-NXL-LS | B19: Quotation Sent | F19: H.M.I PROFACE GP-4501TW, model= PFxGP4501TADW, 24V, 0.71AYenchen super coater m/c model= YC-SC-170F, no.= OB320 160090 capacity=0.8-1.4 Kg/batch 1 EA | G19: Muhammad Ahsan Sadiq Assistant manager Technical purchase | Procurement | Ext: 1409 Martin Dow Marker Ltd D-7, Shaheed-e-Millat Road Karachi-75350, Pakistan UAN : +92 21 111 523 523 Cell: +92-3166550042 Ext: 1409 https://martindowmarker.com/ | K19: Send
A20: AJPG-AVS-WU | B20: Quotation Sent | F20: FLUKE 376FC 4 pcs | G20: Wilson Bulembo Operations Supervisor Novotech Enterprises Limited P.O.Box 10692 Tausi Street No.5,Mikocheni B, Dar-es-salaam, Tanzania, Mobile: +255 (0774) 888831 | Direct +255 (0763) 082645 Email: info@novotechtz.com |info@novotechtz.co.tz| novotech13@gmail.com Website: www.novotechtz.com
A21: AKRO-IZR-WN | B21: Inquiry received by e-mail | F21: Fuji Electric RYS302S3-RPS FALDIC | G21: Abdul Majid National Care Pack Pvt Ltd. Cell. 0092 300 8252089. | K21: Send
A22: AKYP-EZJ-XJ | B22: Request for further information sent to customer | F22: Chemical Pump Caustic Soda NaOH 50% Sodium Hypochlorite NaOCL 13% HCL | G22: Nobel Enterprises Karachi Pakistan nobel.enterprises@yahoo.com info@nobelent.com (021) 34979978
A23: AMHE-UUO-IR | F23: DIGITEN 22mm YELLOW LED Flash Alarm 80dB Indicator Light Lamp with Buzzer Color : Yellow Volt : AC 220V 03 Nos | G23: ='Projects sheet 3'!G975 -> Mirza Imran Baig Senior Buyer, In-direct Sourcing Procurement, Pakistan GSK 35 Dockyard Road, West Wharf, Karachi 74000, Pakistan Email mirza.i.baig@gsk.com Tel +92 21 35274743 Ext: 4743 | K23: Send
A24: ANNR-BOT-SH | B24: Inquiry received by e-mail | F24: Required spare parts of air compressor Make boge Germany Model # SLF 75-3 Serial # 5139398 & 5094203 Rate of flow = 2.10 – 8.50 cum/min Max service pressure = 10 bar Motor power 55 kw . SPARE PRTS Wearing part of MPV = 02 2230337671 Solonaid Valve =01 644006301 Wearing part of intake =01 2420088671 Wearing part of oil regulator =01 2420164671 Suction hose pipe = 01 529001410 Temperature Sensor =01 639002803 Service kit = 03 | G24: Saeed Ahmed Barrett Hodgson Pakistan | K24: Send
A25: ANWW-IFC-VR | F25: 1090000055 CONNECTION PLATE FOR MOTOR 4KW, SIZE: 4MM, WITH DELTA LINK COMPLETE (COMPLETE) EA 08 1090000056 CONNECTION PLATE FOR MOTOR 5.5KW TYPE - : ILA7130-4AA60-Z,TYPE 132- S-4 WITH DELTA LINK(COMPLETE) EA 08 1090000057 CONNECTION PLATE FOR MOTOR 11KW TYPE Y160M2-6 WITH DELTA LINK MPLETE) EA 05 1090000052 CONNECTION PLATE FOR 15KW MOTOR EA 05 1090000059 CONNECTION PLATE FOR MOTOR 18.5KW TYPEY180M-4WITH DELTA LINK MPLETE) EA 05 1090000060 CONNECTION PLATE FOR 45KW MOTOR, TYPE:- Y225M-4WITH DELTA LINK COMPLETE) EA 05 1090005828 TERMINAL PLATE 75KW EA 05 1090000061 CONNECTION PLATE FOR MOTOR 90KW TYPE:- 280S-4 WITH DELTA LINK PLETE) EA 05 | G25: =G15 -> Riffat Tahira Procurement Officer Processing Section Department of Procurement Bestway Cement Limited | 8th Floor | UBL Building, Jinnah Avenue | Islamabad 44000, Pakistan. Tel: +92 51 835 5139 | UAN:+92 51 111 111 722 EXT: 324 Website: www.bestway.com.pk E-mail: riffat.tahira@bestway.com.pk
A26: AOVU-XFK-XN | F26: 1090010887 CONNECTION/TERMINA L PLATE FOR SEW MOTOR TYPE DT 63 N4,0.16 KW EA 06 1090010888 CONNECTION/TERMINA L PLATE FOR SEW MOTOR TYPE DT 71 D4, 0.37 KW EA 06 1090010889 CONNECTION/TERMINA L PLATE FOR SEW MOTOR TYPE RF 40DT 80N4,0.75 KW EA 06 1090010890 CONNECTION/TERMINA L PLATE FOR SEW MOTOR TYPE RF 73DT 100LS4, 2.2 KW EA 06 1090010891 CONNECTION/TERMINA L PLATE FOR SEW MOTOR TYPE R 97 DV 112M4, 4 KW EA 06 1090010892 CONNECTION/TERMINA L PLATE FOR SEW MOTOR TYPE R 87 DV 132M4, 7.5 KW EA 06 1090010893 CONNECTION/TERMINA L PLATE FOR MOTOR TYPE UD 63 SGD,0.25 KW EA 06 1090010894 CONNECTION/TERMINA L PLATE FOR ABB MOTOR TYPE MT100 LA28-8 FF-165,0.75 KW EA 06 1090010895 CONNECTION/TERMINA L PLATE FOR ABB MOTOR TYPE MT90 L24-F-165,MK1007S,1.1 KW EA 06 1090010896 CONNECTION/TERMINA L PLATE FOR ABB MOTOR TYPE M2AA 090 L-2, 2.2 KW EA 06 1090010897 CONNECTION/TERMINA L PLATE FOR ABB MOTOR TYPE M3AA 132-A4, 7.5 KW EA 06 1090010898 CONNECTION/TERMINA L PLATE FOR SIEMENS MOTOR TYPE 1LA 2080-4AA93, 0.55 KW EA 06 1090010899 CONNECTION/TERMINA L PLATE FOR SIEMENS MOTOR TYPE 1LG6-283-2AB91-Z, 90 KW EA 06 1090010900 CONNECTION/TERMINA L PLATE FOR FRIEDRICH SCHWINGTECHNIK MAKE VIBRATOR MOTOR TYPE EX 700-6, 3 KW EA 06 1090010901 CONNECTION/TERMINA L PLATE FOR MOTOR TYPE UD 63 SGD,0.25 KW EA 06 | G26: =G25 -> Riffat Tahira Procurement Officer Processing Section Department of Procurement Bestway Cement Limited | 8th Floor | UBL Building, Jinnah Avenue | Islamabad 44000, Pakistan. Tel: +92 51 835 5139 | UAN:+92 51 111 111 722 EXT: 324 Website: www.bestway.com.pk E-mail: riffat.tahira@bestway.com.pk
A27: AOWX-WYW-QD | F27: Amber Color Glass Bottle 15ml with sealed Caps ,Glass Type -1 CNW –Germany or You may also quote any best Quality Brand i.e Duran, Pyrex & Lauda, Glassco. etc. 2,000 Nos | G27: =G4 -> Afzal Ghani, PROCUREMENT OFFICER Postal Address: P.O Ferozsons, Amangarh, Nowshera, K.P.K, |pro.nowshera@ferozsons-labs.com|Website:www.ferozsons-labs.com|0923-650145, 0312-9486757,03458553396|FAX: 0923-611302|
A28: APCQ-OIW-ZH | B28: Quotation Sent | F28: 6ES7214-1AG40-0XBO, S7 1200, Qty 1 6ES7222-1HH32-0XBO, 16DO Card, Qty 3 | G28: junaid@raeng.com Qazi Junaid junaid@raeng.com R.A ENGINEERING & SERVICES (PVT) LTD.
A29: APFV-LMQ-KI | B29: Quotation Sent | F29: Wintek HMI 7 INCH | G29: Qazi Junaid junaid@raeng.com R.A ENGINEERING & SERVICES (PVT) LTD.
A30: APNA-ULC-NM | F30: Portable Dehumidifier Model # 36B | G30: Helix Pharma Umair
A31: APXH-VKY-EG | F31: GSM data Logger with digital and analog signal for Alarm | G31: Helix Pharma Umair
A32: AQCX-UYY-EX | B32: Inquiry received by e-mail | F32: Killian Machine LX hydraulic cylinder complete set or Seal kit Round-Zylinder Z100 -101 40/20/20-201-100 40/20/20-201 503 KOM 1C 455 picture attached | G32: Muhammad Faizan Electronics Maintenance Officer, GlaxoSmithKline F-268 S.I.T.E., Karachi, Pakistan Email muhammad.8.faizan@gsk.com Cell +92-304-0941792 | H32: https://hollandmotiongroup.com/en/wp-content/uploads/sites/2/2019/02/Brochure-Round-Cylinder-Z100.pdf
A33: AQSB-BOQ-BG | B33: Quotation Sent | F33: Hangcha battery operated stacker controller, D.C motor controller Part no: 360104220 Voltage: 24-36V Model: 1243-4220 Currnt:200A. | G33: Hussain Riaz | Assistant Manager Procurement The Searle Company Limited Address: F-319 SITE, Karachi, Pakistan Work: +(92-21) 3257-8001-7 | Ext: 3084 Cell: +(92) 333 3829055 Email:Hussain.riaz@searlecompany.com | K33: Send
A34: AQXR-RLZ-DC | F34: Pls check the Icar capacitor Model: Msr25-B-1-85: 100pcs | G34: Công Sang Nguyễn <cosavn@gmail.com> VIETNAM
A35: ARAJ-SOV-ZA | F35: Eaton P611 - Switched socket, 13A, 1G, 1p White | G35: Agha Khan Hospital Bright Engineering <brightengg.pk@gmail.com>
A36: ARFV-YUB-TS | B36: Inquiry Letter and Database Ready | F36: FPF Filter Fans IP54 Single Phase QTY: 02 Complete assembly with fan & Filters Model: FPF13KPU 115BE-110 Voltage: 110/115 Vac 50/60Hz Power: 18/20 watt 02: Electrical Cabinet Filter QTY: 06 Cut Out Size: 177*177mm IP: 55 G4 Filter Made in China | G36: Ashraf Butt CHC Procurement Officer GlaxoSmithKline CHC Pakistan Limited. 35 - Dockyard Road, west wharf , Karachi-74000, Pakistan Tel: +92 21 32315478-82 & (Dir) 35274744 UAN:+92 21 111 475 725 (Ext: 4744) | K36: Send
A37: ARRR-WYC-QQ | B37: Quotation Sent | F37: Dispensing booth QTY 2 URS ATTACHED | G37: Syed Nouman Ali Zaidi Deputy Manager Engineering AGP Limited. B-23-C, S.I.T.E., Karachi - 75700, Pakistan. UAN: +92-21-111247247 (Ext. 317) nouman.ali@agp.com.pk | K37: Send
A38: ARUA-XMP-XF | B38: Quotation Sent | F38: Indicator Reagent, Gebruder Heyl, 8028033, 500 ml | G38: Muhammad Nauman Tariq Assistant Manager Engineering 00923434146319 +92-42-35297273-5 Ext: 519 m.nauman@dynatispakistan.com
A39: ARUM-VAW-RP | B39: Inquiry letter sent | F39: 1070021671 BACKSTOP CLUTCH FOR GEARBOX N 20,3,700NM, BORE 130DH7,120KG OF COAL RECLAIMER INCLINED BELT, TYPE OF GEARBOX:ZQ850-5, REDUCTION RATIO: 50, DRIVING MOTOR POWER:30KW, JIANGSU TAILONG DECELARATOR MACHINERY CO.LTD. CHINA. EA 1 | G39: =G26 -> Riffat Tahira Procurement Officer Processing Section Department of Procurement Bestway Cement Limited | 8th Floor | UBL Building, Jinnah Avenue | Islamabad 44000, Pakistan. Tel: +92 51 835 5139 | UAN:+92 51 111 111 722 EXT: 324 Website: www.bestway.com.pk E-mail: riffat.tahira@bestway.com.pk | K39: Send
A40: ASSE-UHQ-YV | B40: Quotation Sent | F40: Through Beam (Fork) Photoelectric Sensor QTY: 02 Part No: BGL 120A-001-S49 Make: BALLUFF Through Beam (Fork) Photoelectric Sensor QTY: 02 Part No: BGL 180A-001-S49 Make: BALLUFF Inductive Sensor QTY: 02 Part No: BES M12ME-PSC40B-S04G-003 Make: BALLUFF Inductive Sensor QTY: 02 Part No: BES M08MI-PSC20B-S49G Make: BALLUFF Inductive Sensor QTY: 02 Part No: BES M12ME-PSC40B-S04G-003 Make: BALLUFF | G40: "Mirza Imran Baig Senior Buyer, In-direct Sourcing Procurement, Pakistan GSK 35 Dockyard Road, West Wharf, Karachi 74000, Pakistan Email mirza.i.baig@gsk.com Tel +92 21 35274743 Ext: 4743 " | K40: Send
...

Sheet Projects sheet 3
B1: Internal Status | C1: Project External Process | D1: Enquiry Came through | E1: Date of enquiry | F1: Customer Requirement Arsalan | G1: CUSTOMER DETAILS | H1: Comments ANY ONE | I1: Enquiry Arrival Date | J1: LINKS STATUS | K1: ACKNOWEDGMENT | L1: Analysis of Customer Enquiry Zafar | M1: Database Prepared by Saad/Kaif/Zafar/Maaz | N1: Enquiry Analysis & links provided by | O1: Enquiry Letter Made and Sent by | P1: Supplier email checked Yasir/Saad/ Arsalan/Zafar | Q1: Price Calculated by Arsalan | R1: Quotation Prepared by | S1: Quotation Follow up done by | T1: Order Processed By | U1: Payment Follow up Done by | V1: Number of Quotation Received | W1: Name of Database | X1: Weblinks | Y1: Weblink status | AA1: Project code Raw
A2: =_xludf.CONCAT(AH2,_xludf.CONCAT("-",AI2)) -> #NAME? | B2: Quotation Sent | D2: Qamar uddin | F2: Dissolution test apparatus with 12 vessels | G2: Barrett Hodgson Pakistan (Pvt) Ltd. saeed.ahmed@BarrettHodgson.com general.purchase@barretthodgson.com | H2: 9M9-5FR-JEY-TZZI QHD-RAK-4Y3-K055 KU8-TAB-YZX-5A1X check above codes for old quotation Hasan: Quotation Sent on 15-04-19 Hasan: Quotation validity reminder sent on 22-04-19 | I2: 43563 | J2: =IF(X2="","LINKS REQUIRED",IF(X2="Completed","LINKS HARVESTED","LINKS AVAILABLE")) -> LINKS REQUIRED | AA2: 3TEBFSTXUYK3IOU | AB2: =LEFT(AA2,6) -> 3TEBFS | AC2: =LEFT(AB2,3) -> 3TE | AD2: =RIGHT(AB2,3) -> BFS | AE2: =RIGHT(AA2,7) -> UYK3IOU | AF2: =LEFT(AE2,4) -> UYK3 | AG2: =RIGHT(AE2,3) -> IOU | AH2: =_xludf.CONCAT(AC2,_xludf.CONCAT("-",AD2)) -> #NAME? | AI2: =_xludf.CONCAT(AF2,_xludf.CONCAT("-",AG2)) -> #NAME?
A3: =_xludf.CONCAT(AH3,_xludf.CONCAT("-",AI3)) -> #NAME? | B3: Request for further information sent to customer | D3: Qamar uddin | F3: Liquid borne particle counter | G3: Barrett Hodgson Pakistan (Pvt) Ltd. saeed.ahmed@BarrettHodgson.com general.purchase@barretthodgson.com | H3: Arsalan: forwaded supplier questions to Barret | I3: 43563 | J3: =IF(X3="","LINKS REQUIRED",IF(X3="Completed","LINKS HARVESTED","LINKS AVAILABLE")) -> LINKS HARVESTED | M3: Saad | O3: Saad | W3: liquid borne particle counter | X3: Completed | Y3: https://www.google.com/search?newwindow=1&biw=1745&bih=852&ei=pdiqXLC6K9GUkgXc3YrQAg&q=liquid+borne+particle+counter+manufacturers&oq=liquid+borne+particle+counter+manufa&gs_l=psy-ab.1.0.0i22i30.7214.10829..12181...0.0..0.186.1279.0j7......0....1..gws-wiz.......0i71j0.yIL2-8f4Pew https://www.google.com/search?newwindow=1&biw=1745&bih=852&ei=stiqXNjmHOTjkgX9_ZDQAg&q=liquid+borne+particle+counter+suppliers&oq=liquid+borne+particle+counter+suppliers&gs_l=psy-ab.3..33i160.18364.20827..20980...0.0..0.222.1764.0j6j3......0....1..gws-wiz.......0i71j35i39j0j0i22i30j33i22i29i30j33i21j33i13i21.aZIHlBwTD58 | AA3: 3UXQ3I9XHBN89ID | AB3: =LEFT(AA3,6) -> 3UXQ3I | AC3: =LEFT(AB3,3) -> 3UX | AD3: =RIGHT(AB3,3) -> Q3I | AE3: =RIGHT(AA3,7) -> HBN89ID | AF3: =LEFT(AE3,4) -> HBN8 | AG3: =RIGHT(AE3,3) -> 9ID | AH3: =_xludf.CONCAT(AC3,_xludf.CONCAT("-",AD3)) -> #NAME? | AI3: =_xludf.CONCAT(AF3,_xludf.CONCAT("-",AG3)) -> #NAME?
A4: =_xludf.CONCAT(AH4,_xludf.CONCAT("-",AI4)) -> #NAME? | B4: Quotation Sent | D4: A. Anwar Khan | F4: Current Transducer Model:COR IA AC Make: REVALCO INPUT lA, 5A AC OUTPUT SELECTABLE V-DC 1.5-10 mA DC 1.5-10-20 qty: 4 | G4: Engro Fertilizer Muhammad Baqar Ali Cell #:+923008690335 Email:mbali@engro.com | H4: Hasan: Quotation sent on 09-04-19 Hasan: Quotation validity reminder sent (16-04-19) | I4: 43562 | J4: =IF(X4="","LINKS REQUIRED",IF(X4="Completed","LINKS HARVESTED","LINKS AVAILABLE")) -> LINKS HARVESTED | M4: Maaz | O4: Saad | W4: current transducer (REVALCO) | X4: Completed | Y4: https://www.google.com/search?newwindow=1&biw=1745&bih=852&ei=PtmqXOSUMK3osAfc6p6gCQ&q=REVALCO+COR+IA+&oq=REVALCO+COR+IA+&gs_l=psy-ab.3..35i39j0i22i30l2.129088.129088..129520...0.0..0.306.306.3-1......0....1..gws-wiz.F3PpfaLFglk https://www.google.com/search?newwindow=1&biw=1745&bih=852&ei=wdmqXOjHC4vhkgXs-KKQCg&q=revalco+cor+ia+ac+current+transducer&oq=REVALCO+COR+IA&gs_l=psy-ab.1.2.35i39l2j0i22i30.11453.14852..16775...1.0..0.310.899.2-2j1......0....1..gws-wiz.......0i22i10i30.pbO_olUQ_aw https://www.google.com/search?newwindow=1&biw=1745&bih=852&ei=0tmqXLeLL8SMkgXWhp64Dw&q=revalco+suppliers&oq=revalco+suppliers&gs_l=psy-ab.3..0.18952.28039..28928...0.0..0.287.2788.2-10......0....1..gws-wiz.......35i39j0i20i263j0i22i30.FY6okmunimY | AA4: 4X87RUE7HX4Z5DX | AB4: =LEFT(AA4,6) -> 4X87RU | AC4: =LEFT(AB4,3) -> 4X8 | AD4: =RIGHT(AB4,3) -> 7RU | AE4: =RIGHT(AA4,7) -> HX4Z5DX | AF4: =LEFT(AE4,4) -> HX4Z | AG4: =RIGHT(AE4,3) -> 5DX | AH4: =_xludf.CONCAT(AC4,_xludf.CONCAT("-",AD4)) -> #NAME? | AI4: =_xludf.CONCAT(AF4,_xludf.CONCAT("-",AG4)) -> #NAME?
A5: =_xludf.CONCAT(AH5,_xludf.CONCAT("-",AI5)) -> #NAME? | B5: Quotation Sent | D5: A. Anwar Khan | F5: Positive Displacement Air Blower Model GM4S Make Aerzen , excluding Electric motor for CF silo, | G5: STAR IMPEX INTERNATIONAL Suite # 5, 3rd Floor Imtiaz Centre, Gulberg II, Main Market, Lahore, 54660, Pakistan Mohammad Abdullah | Manager Commercial Tel: +92-42-35712969 Email: abdullah@starimpex.com | H5: Hasan: Quotation sent on 18-04-19 Hasan: Quotation validity reminder sent (25-04-19) | I5: 43562 | J5: =IF(X5="","LINKS REQUIRED",IF(X5="Completed","LINKS HARVESTED","LINKS AVAILABLE")) -> LINKS HARVESTED | M5: Maaz | O5: Saad | W5: Positive Displacement Air Blower (Aerzen) | X5: Completed | Y5: https://www.google.com/search?newwindow=1&ei=AdqqXImzN4j5sAfdxpewAQ&q=Aerzen+GM4S&oq=Aerzen+GM4S&gs_l=psy-ab.3...4941.7964..8245...0.0..0.288.1106.2-4......0....1j2..gws-wiz.......0i71j35i39.eLAGPVJcO30 https://www.google.com/search?newwindow=1&ei=C9qqXMeLBci1sAf7oLMw&q=Aerzen+GM4S+suppliers&oq=Aerzen+GM4S+suppliers&gs_l=psy-ab.3...7970.11802..12978...0.0..0.373.2948.2-7j3......0....1..gws-wiz.......0i71j0i22i30j33i160.fZu-rZ2fR_Q | AA5: 4XJS7MZIFM92BGS | AB5: =LEFT(AA5,6) -> 4XJS7M | AC5: =LEFT(AB5,3) -> 4XJ | AD5: =RIGHT(AB5,3) -> S7M | AE5: =RIGHT(AA5,7) -> FM92BGS | AF5: =LEFT(AE5,4) -> FM92 | AG5: =RIGHT(AE5,3) -> BGS | AH5: =_xludf.CONCAT(AC5,_xludf.CONCAT("-",AD5)) -> #NAME? | AI5: =_xludf.CONCAT(AF5,_xludf.CONCAT("-",AG5)) -> #NAME?
A6: =_xludf.CONCAT(AH6,_xludf.CONCAT("-",AI6)) -> #NAME? | B6: Quotation Sent | D6: A. Anwar Khan | F6: Choke 250 W (HID BALLAST) Rating 220V-AC. Model: BSNE 250L-3001TS, 9137 130 194 :250W Manufacturer: PHILIPS Qty: 25 SI 51 Plus Ignitor, wattage : 250-400-1000W Voltage : 220V AC -240V AC fn :50/60Hz Manufacturer: PHILIPS Qty: 30 Due Date 11.04.2019 | G6: Muhammad Baqar Ali Cell #:+923008690335 Email:mbali@engro.com RFQ Number 3700022339 | H6: Hasan: Quotation sent on 11-04-19 Hasan: Quotation validity reminder sent (18-04-19) | I6: 43563 | J6: =IF(X6="","LINKS REQUIRED",IF(X6="Completed","LINKS HARVESTED","LINKS AVAILABLE")) -> LINKS HARVESTED | M6: Maaz | O6: Saad | W6: Choke 250 W (HID BALLAST) (PHILIPS) | X6: Completed | Y6: https://www.google.com/search?q=BSNE+250L-3001TS&oq=BSNE+250L-3001TS&aqs=chrome..69i57&sourceid=chrome&ie=UTF-8 https://www.google.com/search?newwindow=1&ei=LCCrXNTyLo2rgwfYyJzYCQ&q=BSNE+250L-3001TS+suppliers&oq=BSNE+250L-3001TS+suppliers&gs_l=psy-ab.3..33i160l2.77140.79418..79595...0.0..0.609.3443.4-4j3......0....1..gws-wiz.......35i302i39.NdSw5i5wD_M https://www.google.com/search?q=SI+51+Plus+Ignitor&oq=SI+51+Plus+Ignitor&aqs=chrome..69i57&sourceid=chrome&ie=UTF-8 | AA6: 41WJDX57X1BV8TC | AB6: =LEFT(AA6,6) -> 41WJDX | AC6: =LEFT(AB6,3) -> 41W | AD6: =RIGHT(AB6,3) -> JDX | AE6: =RIGHT(AA6,7) -> X1BV8TC | AF6: =LEFT(AE6,4) -> X1BV | AG6: =RIGHT(AE6,3) -> 8TC | AH6: =_xludf.CONCAT(AC6,_xludf.CONCAT("-",AD6)) -> #NAME? | AI6: =_xludf.CONCAT(AF6,_xludf.CONCAT("-",AG6)) -> #NAME?
A7: =_xludf.CONCAT(AH7,_xludf.CONCAT("-",AI7)) -> #NAME? | B7: Request for further information sent to customer | D7: Qamar uddin | F7: Sejong dust collector cartage filter Model SFC-170FSH Serial number SC 11278 Description Cartridge filter Material Polyester Size as in manual Ø145MM X 600L x 75th Required quantity 16 nos | G7: Ashraf Butt Procurement Officer GlaxoSmithKline Consumer Healthcare Pakistan Ltd. 35 - Dockyard Road, west wharf , Karachi Tel: 35274744 (Ext: 4744) ashraf.x.butt@gsk.com Contact Person: Mr. Zakir Raza - 03112317017 - 0222109534 | H7: Boss requested more informaiton on filter | I7: 43563 | J7: =IF(X7="","LINKS REQUIRED",IF(X7="Completed","LINKS HARVESTED","LINKS AVAILABLE")) -> LINKS REQUIRED | AA7: 42B8NUJHXUJHGC4 | AB7: =LEFT(AA7,6) -> 42B8NU | AC7: =LEFT(AB7,3) -> 42B | AD7: =RIGHT(AB7,3) -> 8NU | AE7: =RIGHT(AA7,7) -> XUJHGC4 | AF7: =LEFT(AE7,4) -> XUJH | AG7: =RIGHT(AE7,3) -> GC4 | AH7: =_xludf.CONCAT(AC7,_xludf.CONCAT("-",AD7)) -> #NAME? | AI7: =_xludf.CONCAT(AF7,_xludf.CONCAT("-",AG7)) -> #NAME?
A8: =_xludf.CONCAT(AH8,_xludf.CONCAT("-",AI8)) -> #NAME? | B8: Quotation Sent | D8: A. Anwar Khan | F8: 3 PHASE INDUCTION MOTOR WITH COOLING FAN, TYPE:VFD MOTOR ,YVF2-132S2-2,7.5KW,14.5A, 380V,2900RPM,25.6NM,CL. F, 5-50HZ,50-100HZ,IM V1,COOLING,FAN:TYPE: G-132,80W,380V,0.41A,1300RPM,AIR VOLUME 760M3/H,AIR PRESSURE 50PA,LINE-II NOS 1 3 PHASE INDUCTION MOTOR, TYPE: 132M-4 , 7.5KW, 14.8A, 1440RPM, IP55, 50HZ, 400V, CONN. D, PF 0.84, INSCL. F,DUTY S1, IM B5 FOR LINE-II NOS 1 YVF2-132M-4 SPI # 603 & RFQ # 6273-ELEC | G8: Best Regards, Muhammad Rehan Anwar Officer Procurement Department of Procurement Bestway Cement Limited | 8th Floor | UBL Building, Jinnah Avenue | Islamabad 44000, Pakistan. Tel: +92 51 835 5118 | Fax: +92 51 265 4865 | UAN:+92 51 111 111 722 Website: www.bestway.com.pk E-mail: rehan.anwar@bestway.com.pk | H8: https://www.google.com/search?newwindow=1&ei=SCqsXNrcJ8y4mAWskpDYCQ&q=siemens+YVF2-132S2-2&oq=siemens+YVF2-132S2-2&gs_l=psy-ab.3...4903.8205..8326...2.0..0.145.1168.0j9......0....1..gws-wiz.......0i13i30j0i13i5i30.c0bAJH7CDZo both motors specs are in first link of above link Hasan: Quotation sent on 11-04-19 Hasan: Quotation validity reminder sent Maaz: inquiry letter again fly on 3 phase motor merged database and the CODE no. is 42M-J3H-XXCC-JLE-1 (30-Apr-19) | I8: 43563 | J8: =IF(X8="","LINKS REQUIRED",IF(X8="Completed","LINKS HARVESTED","LINKS AVAILABLE")) -> LINKS HARVESTED | M8: Maaz | O8: Saad | W8: 3 PHASE INDUCTION MOTOR YVF2 | X8: Completed | Y8: http://www.beide-motor.cn/ssml/lxwm.asp https://www.google.com/search?newwindow=1&ei=SCqsXNrcJ8y4mAWskpDYCQ&q=siemens+YVF2-132S2-2&oq=siemens+YVF2-132S2-2&gs_l=psy-ab.3...4903.8205..8326...2.0..0.145.1168.0j9......0....1..gws-wiz.......0i13i30j0i13i5i30.c0bAJH7CDZo https://www.google.com/search?newwindow=1&ei=UiqsXOj5AeLUmAXurKTQDg&q=siemens+YVF2-132M-4&oq=siemens+YVF2-132M-4&gs_l=psy-ab.3...512527.512527..513427...0.0..0.151.151.0j1......0....2j1..gws-wiz.PM7Dorj_Vpo | AA8: 42MJ3HPSXXCCJLE | AB8: =LEFT(AA8,6) -> 42MJ3H | AC8: =LEFT(AB8,3) -> 42M | AD8: =RIGHT(AB8,3) -> J3H | AE8: =RIGHT(AA8,7) -> XXCCJLE | AF8: =LEFT(AE8,4) -> XXCC | AG8: =RIGHT(AE8,3) -> JLE | AH8: =_xludf.CONCAT(AC8,_xludf.CONCAT("-",AD8)) -> #NAME? | AI8: =_xludf.CONCAT(AF8,_xludf.CONCAT("-",AG8)) -> #NAME?
A9: =_xludf.CONCAT(AH9,_xludf.CONCAT("-",AI9)) -> #NAME? | B9: Request for further information sent to customer | D9: A. Anwar Khan | F9: 3-PHASE INDUCTION MOTOR INVERTER DUTY, TYPE: DRE180L4/TF, 22 KW, 42AMP, 400V, 1480 RPM, IM B5, MAKE: SEW EURODRIVE FOR LINE-II 3-PHASE INDUCTION MOTOR INVERTER DUTY, TYPE: HJN1 100L2-4, 3 KW, 6.18 AMP, 400V, 1425 RPM, IM V1, MAKE: SEW EURODRIVE FOR LINE-II SPI # 602 & RFQ # 6245-ELEC | G9: Best Regards, Muhammad Rehan Anwar Officer Procurement Department of Procurement Bestway Cement Limited | 8th Floor | UBL Building, Jinnah Avenue | Islamabad 44000, Pakistan. Tel: +92 51 835 5118 | Fax: +92 51 265 4865 | UAN:+92 51 111 111 722 Website: www.bestway.com.pk E-mail: rehan.anwar@bestway.com.pk | H9: Nameplate requested databse already availble SEW Request for further information sent to customer (No Answer) | I9: 43556 | J9: =IF(X9="","LINKS REQUIRED",IF(X9="Completed","LINKS HARVESTED","LINKS AVAILABLE")) -> LINKS REQUIRED | M9: Internal Office Staff (All for one) | O9: Saad | AA9: 4AHISH7ACSDHUFS | AB9: =LEFT(AA9,6) -> 4AHISH | AC9: =LEFT(AB9,3) -> 4AH | AD9: =RIGHT(AB9,3) -> ISH | AE9: =RIGHT(AA9,7) -> CSDHUFS | AF9: =LEFT(AE9,4) -> CSDH | AG9: =RIGHT(AE9,3) -> UFS | AH9: =_xludf.CONCAT(AC9,_xludf.CONCAT("-",AD9)) -> #NAME? | AI9: =_xludf.CONCAT(AF9,_xludf.CONCAT("-",AG9)) -> #NAME?
A10: =_xludf.CONCAT(AH10,_xludf.CONCAT("-",AI10)) -> #NAME? | B10: Quotation Sent | D10: A. Anwar Khan | F10: 3 PHASE INDUCTION MOTOR, TYPE: 1LA7063-4AB12, 63M, IM B14, 0.18KW, 400V, 0.58A, Y-CONN, 1350RPM, IP55, 50HZ FOR LINE-II NOS 1 SPI # 603 & RFQ # 6273-ELEC | G10: Best Regards, Muhammad Rehan Anwar Officer Procurement Department of Procurement Bestway Cement Limited | 8th Floor | UBL Building, Jinnah Avenue | Islamabad 44000, Pakistan. Tel: +92 51 835 5118 | Fax: +92 51 265 4865 | UAN:+92 51 111 111 722 Website: www.bestway.com.pk E-mail: rehan.anwar@bestway.com.pk | H10: Hasan: Quotation sent on 15-04-19 Hasan: Quotation validity reminder sent on 22-04-19 | I10: 43563 | J10: =IF(X10="","LINKS REQUIRED",IF(X10="Completed","LINKS HARVESTED","LINKS AVAILABLE")) -> LINKS HARVESTED | M10: Maaz | N10: Anwar Khan | O10: Saad | W10: 3 PHASE INDUCTION MOTOR 1LA7063 | X10: Completed | Y10: https://www.google.com/search?q=1LA7063-4AB12&oq=1LA7063-4AB12&aqs=chrome..69i57j0l3.527j0j9&sourceid=chrome&ie=UTF-8 https://www.google.com/search?newwindow=1&ei=ICusXMyUBMODoASc27D4Aw&q=1LA7063-4AB12+suppliers&oq=1LA7063-4AB12+suppliers&gs_l=psy-ab.3...337612.340898..341322...0.0..0.151.1274.0j10......0....1..gws-wiz.......0i30j0i5i30j0i13i30j0i22i30j33i160.VlNWkLSy24U | AA10: 4BCWTLC8SSGKW8O | AB10: =LEFT(AA10,6) -> 4BCWTL | AC10: =LEFT(AB10,3) -> 4BC | AD10: =RIGHT(AB10,3) -> WTL | AE10: =RIGHT(AA10,7) -> SSGKW8O | AF10: =LEFT(AE10,4) -> SSGK | AG10: =RIGHT(AE10,3) -> W8O | AH10: =_xludf.CONCAT(AC10,_xludf.CONCAT("-",AD10)) -> #NAME? | AI10: =_xludf.CONCAT(AF10,_xludf.CONCAT("-",AG10)) -> #NAME?
A11: =_xludf.CONCAT(AH11,_xludf.CONCAT("-",AI11)) -> #NAME? | B11: Quotation Sent | D11: A. Anwar Khan | F11: Sachet filling and sealing machine complete S.S. body sealing : four side sealing sealing type : graphic product : free flowing powder weight range : 5 - 25 gms free flowing powder filling : cup type folder size: 170 mm If possible we need batch # and expiry in sealer as well as hot ink roller printer installed ( so we can use both options simultaneously ) capacity : > 50 bags per min | G11: Qasim Mehmood Cell # 0333 2166792 Focus and Rulz Pharmaceutical Islamabad | H11: Maaz: merged it with sachet & FFS machine database Hasan: Quotation sent on 15-04-19 Hasan: Quotation validity reminder sent on 22-04-19 | I11: 43564 | J11: =IF(X11="","LINKS REQUIRED",IF(X11="Completed","LINKS HARVESTED","LINKS AVAILABLE")) -> LINKS HARVESTED | M11: Maaz | O11: Saad | W11: Sachet filling and sealing machine | X11: Completed | Y11: https://www.google.com/search?newwindow=1&ei=XL-tXMyJE5mGoAS0l6XgAw&q=Sachet+filling+and+sealing+machine+manufacturers+&oq=Sachet+filling+and+sealing+machine+manufacturers+&gs_l=psy-ab.3..0i22i30.14434.17737..18018...0.0..0.163.2230.0j15......0....1..gws-wiz.......0i71j0j33i22i29i30.5R6L0QTVMcM | AA11: 4BDJNXDRU5GWI05 | AB11: =LEFT(AA11,6) -> 4BDJNX | AC11: =LEFT(AB11,3) -> 4BD | AD11: =RIGHT(AB11,3) -> JNX | AE11: =RIGHT(AA11,7) -> U5GWI05 | AF11: =LEFT(AE11,4) -> U5GW | AG11: =RIGHT(AE11,3) -> I05 | AH11: =_xludf.CONCAT(AC11,_xludf.CONCAT("-",AD11)) -> #NAME? | AI11: =_xludf.CONCAT(AF11,_xludf.CONCAT("-",AG11)) -> #NAME?
A12: =_xludf.CONCAT(AH12,_xludf.CONCAT("-",AI12)) -> #NAME? | B12: Request for further information sent to customer | D12: Qamar uddin | F12: Cartoner Machine mouth 2 pic Pictures in email | G12: Ashraf Butt Procurement Officer GlaxoSmithKline Consumer Healthcare Pakistan Ltd. 35 - Dockyard Road, west wharf , Karachi Tel: 35274744 (Ext: 4744) ashraf.x.butt@gsk.com | I12: 43564 | J12: =IF(X12="","LINKS REQUIRED",IF(X12="Completed","LINKS HARVESTED","LINKS AVAILABLE")) -> LINKS REQUIRED | AA12: 4CIDRQRGTNA1YB9 | AB12: =LEFT(AA12,6) -> 4CIDRQ | AC12: =LEFT(AB12,3) -> 4CI | AD12: =RIGHT(AB12,3) -> DRQ | AE12: =RIGHT(AA12,7) -> TNA1YB9 | AF12: =LEFT(AE12,4) -> TNA1 | AG12: =RIGHT(AE12,3) -> YB9 | AH12: =_xludf.CONCAT(AC12,_xludf.CONCAT("-",AD12)) -> #NAME? | AI12: =_xludf.CONCAT(AF12,_xludf.CONCAT("-",AG12)) -> #NAME?
A13: =_xludf.CONCAT(AH13,_xludf.CONCAT("-",AI13)) -> #NAME? | B13: Inquiry letter sent | D13: Qamar uddin | F13: Becteriological Agar For Molecular Biology 1 KG Biological Indicator-Strips ATCC No.2714 2 EA Bordetella Bronchiseptica ATCC#4617 1 EA Candida Albican ATCC # 10231 1 EA Clostridrium Sporogens ATCC # 11437 1 EA Dextrose Oxoid Cat#LP0071 200 KG E. Coli ATCC# 14169 1 EA E.Coli ATCC # 8739 1 EA Enterococcus Hirac ATCC # 8043 1 EA Pseudomonas Aeroginosa ATCC # 9027 1 EA | G13: saeed.ahmed@BarrettHodgson.com | H13: From first link find all europe distributor and germany nebour countires Saad: Inquiry Letter Sent Again with Ameneded Letter (12 Apr 19) on Merged Bacteria Database | I13: 43565 | J13: =IF(X13="","LINKS REQUIRED",IF(X13="Completed","LINKS HARVESTED","LINKS AVAILABLE")) -> LINKS HARVESTED | M13: Maaz | O13: Saad | W13: Becteriological Agar For Molecular Biology | X13: Completed | Y13: https://www.atcc.org/Support/Find_ATCC_Distributors.aspx https://www.google.com/search?newwindow=1&ei=eYKtXOmyDYT1wAOjsI7IBQ&q=ATCC%23+10231&oq=ATCC%23+10231&gs_l=psy-ab.3..0i22i30l7.21201.21201..22063...0.0..0.115.115.0j1......0....2j1..gws-wiz.......0i71.w46ioEBQmUQ https://www.google.com/search?newwindow=1&ei=kIKtXMaSKMz4hwPS6LO4Dg&q=ATCC+suppliers+in+europe&oq=ATCC+suppliers+in+europe&gs_l=psy-ab.3..33i22i29i30.98873.106711..106825...0.0..0.122.2318.0j20......0....1..gws-wiz.......0i71j35i39j0i67j0j0i20i263j0i22i30j0i22i10i30.FRiEwgTUzqQ | AA13: 4DGUNXICKT4FZ3S | AB13: =LEFT(AA13,6) -> 4DGUNX | AC13: =LEFT(AB13,3) -> 4DG | AD13: =RIGHT(AB13,3) -> UNX | AE13: =RIGHT(AA13,7) -> KT4FZ3S | AF13: =LEFT(AE13,4) -> KT4F | AG13: =RIGHT(AE13,3) -> Z3S | AH13: =_xludf.CONCAT(AC13,_xludf.CONCAT("-",AD13)) -> #NAME? | AI13: =_xludf.CONCAT(AF13,_xludf.CONCAT("-",AG13)) -> #NAME?
A14: =_xludf.CONCAT(AH14,_xludf.CONCAT("-",AI14)) -> #NAME? | B14: Quotation Sent | D14: A. Anwar Khan | F14: PH METER RANGE=0.0 TO 14.0 PH, HAND HELD TYPE, RANGE= 0.014 PH, RESOLUTION= 0.1 PH, ACCURACY= + OR - 0.1 pH, HOLD FUNCTION= YES, MAKE: EU TECH INSTRUMENT, MADE IN MALAYSIA. Qty 02 | G14: Martin Dow Marker Ltd Formerly Merck (Pvt.) Ltd. D-7, Shaheed-e-Millat Road, Karachi-75350, Pakistan UAN : +92 21 111 523 523 Fax : +92 21 3455 92 21 Nasiruddin Khan Manager Sourcing- Technical operations services) | Procurement nasiruddin.khan@martindow.com | H14: Arsalan: EcoTestr pH 1 do work on this Hasan: Quotation sent on 16-04-19 Hasan: Quotation validity reminder sent (23-04-19) | I14: 43565 | J14: =IF(X14="","LINKS REQUIRED",IF(X14="Completed","LINKS HARVESTED","LINKS AVAILABLE")) -> LINKS HARVESTED | M14: Maaz | O14: Maaz | W14: PH METER HAND HELD TYPE | X14: Completed | Y14: http://www.eutechinst.com/contact-offices.html https://www.google.com/search?newwindow=1&biw=1745&bih=852&ei=hqCtXPquGsXbhwPwubPYBQ&q=eutech+instruments+malaysia&oq=EUTECH+INSTRUMENT+mal&gs_l=psy-ab.1.0.0i22i30.110934.112069..113421...0.0..0.119.475.0j4......0....1..gws-wiz.......0i71j0i22i10i30.9N8hUJN6RdE https://www.google.com/search?newwindow=1&biw=1745&bih=852&ei=-KCtXNzeJ42A-Qb67qe4Cg&q=eutech+instruments+ph+meter+suppliers&oq=eutech+instruments+ph+meter+suppl&gs_l=psy-ab.1.0.33i21l2j33i160.172904.176639..177968...0.0..0.208.1014.0j6j1......0....1..gws-wiz.......0i71j35i39j0j0i22i30j33i22i29i30.jdNBhSvhFBA https://www.google.com/search?newwindow=1&ei=Xxu0XKmLE8rfvgT444Iw&q=EcoTestr+pH+1+Eutech+Instruments&oq=EcoTestr+pH+1+Eutech+Instruments&gs_l=psy-ab.3...85233.87376..87896...0.0..0.192.572.0j4......0....1j2..gws-wiz.......0i22i30.MsyQvcUVF5s https://www.google.com/search?newwindow=1&ei=uBu0XOC2D4zSvwSsgonADw&q=EcoTestr+pH+1+Eutech+Instruments+SUPPLIERS&oq=EcoTestr+pH+1+Eutech+Instruments+SUPPLIERS&gs_l=psy-ab.3...10138.11994..12138...0.0..0.150.1370.0j10......0....1..gws-wiz.......0i71j35i302i39j33i160j33i21.nip6Y6Wm1i0 | AA14: 4DTCWASZ9X17QE6 | AB14: =LEFT(AA14,6) -> 4DTCWA | AC14: =LEFT(AB14,3) -> 4DT | AD14: =RIGHT(AB14,3) -> CWA | AE14: =RIGHT(AA14,7) -> 9X17QE6 | AF14: =LEFT(AE14,4) -> 9X17 | AG14: =RIGHT(AE14,3) -> QE6 | AH14: =_xludf.CONCAT(AC14,_xludf.CONCAT("-",AD14)) -> #NAME? | AI14: =_xludf.CONCAT(AF14,_xludf.CONCAT("-",AG14)) -> #NAME?
A15: =_xludf.CONCAT(AH15,_xludf.CONCAT("-",AI15)) -> #NAME? | B15: Quotation Sent | D15: A. Anwar Khan | F15: ENCODER 942670 Z HENGSTLER Encoder 0 543 118/2 RA58-P/0012 EK. 4 2 CICB 10-30VDC = /0.2A/V 1.04 Qty 1 | G15: Mohammad Abdullah | Manager Commercial Tel: +92-42-35712969 Email: abdullah@starimpex.com STAR IMPEX INTERNATIONAL Suite # 5, 3rd Floor Imtiaz Centre, Gulberg II, Main Market, Lahore, 54660, Pakistan | H15: H9A-95-MSC-AB R6U-7X-2EW-PR R81-BS-9NW-4C info@hengstler.com Merge above codes databases and flly the Enquiry Hasan: Quotation sent on 11-04-19 Hasan: Quotation validity reminder sent (18-04-19) | I15: 43565 | J15: =IF(X15="","LINKS REQUIRED",IF(X15="Completed","LINKS HARVESTED","LINKS AVAILABLE")) -> LINKS HARVESTED | M15: Maaz | O15: Saad | W15: HENGSTLER Encoder 942670 Z | X15: Completed | AA15: 4FNJEDZF4FJGS8Y | AB15: =LEFT(AA15,6) -> 4FNJED | AC15: =LEFT(AB15,3) -> 4FN | AD15: =RIGHT(AB15,3) -> JED | AE15: =RIGHT(AA15,7) -> 4FJGS8Y | AF15: =LEFT(AE15,4) -> 4FJG | AG15: =RIGHT(AE15,3) -> S8Y | AH15: =_xludf.CONCAT(AC15,_xludf.CONCAT("-",AD15)) -> #NAME? | AI15: =_xludf.CONCAT(AF15,_xludf.CONCAT("-",AG15)) -> #NAME?
A16: =_xludf.CONCAT(AH16,_xludf.CONCAT("-",AI16)) -> #NAME? | B16: Closed | D16: Qamar uddin | F16: Media bottle 2L ISO LAB | G16: saeed.ahmed@BarrettHodgson.com | H16: (Arsalan)Quantity confirm nai inquiry flow kr di bhang peetay ho | I16: 43566 | J16: =IF(X16="","LINKS REQUIRED",IF(X16="Completed","LINKS HARVESTED","LINKS AVAILABLE")) -> LINKS HARVESTED | M16: Saad | O16: Saad | X16: Completed | Y16: http://www.isolab.de/en-us/contact-info https://www.google.com/search?newwindow=1&biw=1745&bih=852&ei=femuXNGzG4T4vgTcg4agCQ&q=media+bottle+2L+ISOLAB+supplier&oq=media+bottle+2L+ISOLAB+supplier&gs_l=psy-ab.3..33i160.179210.180927..182160...0.0..0.168.1343.0j9......0....1..gws-wiz.......35i302i39.cIHbvsWVwps | AA16: 4IIJXRPFRJRCTZG | AB16: =LEFT(AA16,6) -> 4IIJXR | AC16: =LEFT(AB16,3) -> 4II | AD16: =RIGHT(AB16,3) -> JXR | AE16: =RIGHT(AA16,7) -> RJRCTZG | AF16: =LEFT(AE16,4) -> RJRC | AG16: =RIGHT(AE16,3) -> TZG | AH16: =_xludf.CONCAT(AC16,_xludf.CONCAT("-",AD16)) -> #NAME? | AI16: =_xludf.CONCAT(AF16,_xludf.CONCAT("-",AG16)) -> #NAME?
A17: =_xludf.CONCAT(AH17,_xludf.CONCAT("-",AI17)) -> #NAME? | B17: Closed | D17: Qamar uddin | F17: Media bottle 2L VWR | G17: saeed.ahmed@BarrettHodgson.com | H17: (Arsalan)Quantity confirm nai inquiry flow kr di bhang peetay ho | I17: 43566 | J17: =IF(X17="","LINKS REQUIRED",IF(X17="Completed","LINKS HARVESTED","LINKS AVAILABLE")) -> LINKS HARVESTED | M17: Maaz | O17: Saad | W17: Media bottle 2L VWR | X17: Completed | Y17: https://www.google.com/search?q=%22%40avantorsciences.com%22+Emails&oq=%22%40avantorsciences.com%22+Emails&aqs=chrome..69i57.12927j0j9&sourceid=chrome&ie=UTF-8 https://us.vwr.com/cms/contact_main https://www.google.com/search?newwindow=1&ei=U-muXPa7DsLZvgTi7bOICg&q=media+bottle+2L+VWR+suppliers&oq=media+bottle+2L+VWR+suppliers&gs_l=psy-ab.3..33i160.245931.248787..248907...0.0..0.152.1330.0j10......0....1..gws-wiz.......0i71j35i39j33i22i29i30j33i21.b-33bTZReW4 | AA17: 4K1EN8XET47ADI1 | AB17: =LEFT(AA17,6) -> 4K1EN8 | AC17: =LEFT(AB17,3) -> 4K1 | AD17: =RIGHT(AB17,3) -> EN8 | AE17: =RIGHT(AA17,7) -> T47ADI1 | AF17: =LEFT(AE17,4) -> T47A | AG17: =RIGHT(AE17,3) -> DI1 | AH17: =_xludf.CONCAT(AC17,_xludf.CONCAT("-",AD17)) -> #NAME? | AI17: =_xludf.CONCAT(AF17,_xludf.CONCAT("-",AG17)) -> #NAME?
A18: =_xludf.CONCAT(AH18,_xludf.CONCAT("-",AI18)) -> #NAME? | B18: Quotation Sent | C18: second quotatioin sent | D18: Qamar uddin | F18: 1. Electronic Thermostat (Digital). Make: Novus /Autonics / Omron / Mitsubishi / AKO (Spain). Temperature range: 50 ˚C to 300 ˚C. Inputs: Two PT100 inputs. Outputs: Two dry contact outputs (SPDT). Access Level: Minimum 3 digits Password protection. Quantity: 04 Nos (Controller With Sensor Complete Unit). | G18: Ashraf Butt Procurement Officer GlaxoSmithKline Consumer Healthcare Pakistan Ltd. 35 - Dockyard Road, west wharf , Karachi Tel: 35274744 (Ext: 4744) ashraf.x.butt@gsk.com | H18: Do not put Brand name in enquiry my links include all brands Hasan: Quotation sent on 16-04-19 Hasan: Quotation validity reminder sent on 23-04-19 Hasan: 2nd Quotation sent on 17-04-19 Hasan: Quotation validity reminder sent on 24-04-19 | I18: 43567 | J18: =IF(X18="","LINKS REQUIRED",IF(X18="Completed","LINKS HARVESTED","LINKS AVAILABLE")) -> LINKS HARVESTED | M18: Maaz | O18: Maaz | W18: Electronic Thermostat Digital (All brands) | X18: Completed | Y18: https://www.google.com/search?newwindow=1&ei=kWiwXM_gJ8LTz7sP8beDkAg&q=ako+%28spain%29+electronic+thermostat+%28digital%29+suppliers+-%22pdf%22+-%22amazon%22+-%22ebay%22+-%22youtube%22&oq=ako+%28spain%29+electronic+thermostat+%28digital%29+suppliers+-%22pdf%22+-%22amazon%22+-%22ebay%22+-%22youtube%22&gs_l=psy-ab.3...2285.2285..2578...0.0..0.109.109.0j1......0....1..gws-wiz.8eWJ8gVYVr8 https://www.google.com/search?newwindow=1&q=Mitsubishi+electric+thermostat+(digital)+suppliers+-%22pdf%22+-%22amazon%22+-%22ebay%22+-%22youtube%22&spell=1&sa=X&ved=0ahUKEwisuLXIrMrhAhW1_XMBHW4ACTYQBQgoKAA&biw=1745&bih=852 https://www.google.com/search?newwindow=1&ei=XGiwXNL-GdKYmgefxIL4DQ&q=Omron+electronic+thermostat+%28digital%29+suppliers+-%22pdf%22+-%22amazon%22+-%22ebay%22+-%22youtube%22&oq=Omron+electronic+thermostat+%28digital%29+suppliers+-%22pdf%22+-%22amazon%22+-%22ebay%22+-%22youtube%22&gs_l=psy-ab.3...91378.91646..92265...0.0..0.119.227.0j2......0....1j2..gws-wiz.......0i71j35i39j0i67j0.9uLanjzCZEk https://www.google.com/search?newwindow=1&biw=1745&bih=852&ei=UWiwXK2GD97dz7sP6sO4WA&q=honeywell+electronic+thermostat+%28digital%29+suppliers+-%22pdf%22+-%22amazon%22+-%22ebay%22+-%22youtube%22&oq=honeywell+electronic+thermostat+%28digital%29+suppliers+-%22pdf%22+-%22amazon%22+-%22ebay%22+-%22youtube%22&gs_l=psy-ab.3...117907.117907..118424...0.0..0.101.101.0j1......0....2j1..gws-wiz.......0i71.nzdI7vi4vaU https://www.google.com/search?newwindow=1&biw=1745&bih=852&ei=-GewXIyJOOXbz7sPtPSLgAU&q=Autonics+electronic+thermostat+%28digital%29+suppliers+-%22pdf%22+-%22amazon%22+-%22ebay%22+-%22youtube%22&oq=Autonics+electronic+thermostat+%28digital%29+suppliers+-%22pdf%22+-%22amazon%22+-%22ebay%22+-%22youtube%22&gs_l=psy-ab.3...220907.220907..221928...0.0..0.110.110.0j1......0....2j1..gws-wiz.......0i71.KpyBRO8A3Nc https://www.google.com/search?newwindow=1&biw=1745&bih=852&ei=7WewXJ_gINLDz7sPqcimuAM&q=Novus+electronic+thermostat+%28digital%29+suppliers+-%22pdf%22+-%22amazon%22+-%22ebay%22+-%22youtube%22&oq=Novus+electronic+thermostat+%28digital%29+suppliers+-%22pdf%22+-%22amazon%22+-%22ebay%22+-%22youtube%22&gs_l=psy-ab.3...244824.244824..245686...0.0..0.101.101.0j1......0....2j1..gws-wiz.......0i71.5-Glelb1NJI | AA18: 4KCJ3Y57B12I0QH | AB18: =LEFT(AA18,6) -> 4KCJ3Y | AC18: =LEFT(AB18,3) -> 4KC | AD18: =RIGHT(AB18,3) -> J3Y | AE18: =RIGHT(AA18,7) -> B12I0QH | AF18: =LEFT(AE18,4) -> B12I | AG18: =RIGHT(AE18,3) -> 0QH | AH18: =_xludf.CONCAT(AC18,_xludf.CONCAT("-",AD18)) -> #NAME? | AI18: =_xludf.CONCAT(AF18,_xludf.CONCAT("-",AG18)) -> #NAME?
A19: =_xludf.CONCAT(AH19,_xludf.CONCAT("-",AI19)) -> #NAME? | B19: Quotation Sent | D19: A. Anwar Khan | F19: Motor Cooling Fan (35Watts) Cooling Fan (Ac Axial Fan) Power: 35 watts, Volts: 220-240v 50/60Hz,Amps: 0.29A, Model: FP-108EX-SI-B,Impendance Protected, Size:172x150x51mm, Make: T&B OR EQUIVALENT | G19: Muhammad Baqar Ali Cell #:+923008690335 Email:mbali@engro.com | H19: Hasan: Quotation sent on 16-04-19 Hasan: Quotation validity reminder sent on 23-04-19 | I19: 43566 | J19: =IF(X19="","LINKS REQUIRED",IF(X19="Completed","LINKS HARVESTED","LINKS AVAILABLE")) -> LINKS HARVESTED | M19: Maaz | W19: Motor Cooling Fan (T&B) | X19: Completed | Y19: https://www.google.com/search?q=FP-108EX-SI-B&newwindow=1&source=lnms&sa=X&ved=0ahUKEwifmfbz98fhAhVHgrwKHWwfCvgQ_AUICSgA&biw=1745&bih=852&dpr=1.1 https://www.google.com/search?newwindow=1&biw=1745&bih=852&ei=DSWvXPnuFsiBvwSVpIPgCw&q=T%26B++FP-108EX-SI-B&oq=T%26B++FP-108EX-SI-B&gs_l=psy-ab.3...42068.42345..43201...0.0..0.112.224.0j2......0....2j1..gws-wiz.......0i71.bOZCgjCeNS4 | AA19: 4KXIEAJRBIHZ93A | AB19: =LEFT(AA19,6) -> 4KXIEA | AC19: =LEFT(AB19,3) -> 4KX | AD19: =RIGHT(AB19,3) -> IEA | AE19: =RIGHT(AA19,7) -> BIHZ93A | AF19: =LEFT(AE19,4) -> BIHZ | AG19: =RIGHT(AE19,3) -> 93A | AH19: =_xludf.CONCAT(AC19,_xludf.CONCAT("-",AD19)) -> #NAME? | AI19: =_xludf.CONCAT(AF19,_xludf.CONCAT("-",AG19)) -> #NAME?
A20: =_xludf.CONCAT(AH20,_xludf.CONCAT("-",AI20)) -> #NAME? | B20: Request for further information sent to customer | D20: Qamar uddin | F20: Vacuum pump with filtration assembly | G20: saeed.ahmed@BarrettHodgson.com | I20: 43566 | J20: =IF(X20="","LINKS REQUIRED",IF(X20="Completed","LINKS HARVESTED","LINKS AVAILABLE")) -> LINKS REQUIRED | AA20: 4L3UYZLX7DMHV11 | AB20: =LEFT(AA20,6) -> 4L3UYZ | AC20: =LEFT(AB20,3) -> 4L3 | AD20: =RIGHT(AB20,3) -> UYZ | AE20: =RIGHT(AA20,7) -> 7DMHV11 | AF20: =LEFT(AE20,4) -> 7DMH | AG20: =RIGHT(AE20,3) -> V11 | AH20: =_xludf.CONCAT(AC20,_xludf.CONCAT("-",AD20)) -> #NAME? | AI20: =_xludf.CONCAT(AF20,_xludf.CONCAT("-",AG20)) -> #NAME?
